Workbook

Sheet History
B1: Sheet update 이력
E2: 건축구조설계팀
C3: 수정 내용 | D3: 수정일 | E3: 작성자
B4: 0 | C4: 1차 sheet 완성 - Midas gen 의 ASD 89 적용시에는 휨응력을 My/I 로 적용함. 본 sheet 는 M/S 값을 적용하여 미세한 차이가 있음.(S :공칭단면계수) | D4: 2026.05.21 | E4: 김재동
B5: 1 | C5: Fa2 (K열) 수식 오류 수정 Fa 분모 : (5/3) + (3*세장비/8*Cc) - (Cc^3/8*Cc^3) → (5/3) + (3*세장비/8*Cc) - (세장비^3/8*Cc^3) | D5: 2026.05.22 | E5: 김재동
B6: 2 | C6: Channel 부재 단면 추가 및 변위 산정 table 추가 | D6: 2026.05.26 | E6: 김재동
B7: 3 | C7: Channel 부재 설계 table 추가 | D7: 2026.05.27 | E7: 김재동
B8: 4 | C8: Angle 부재 단면 추가 및 변위 산정 table 추가 | D8: 2026.05.28 | E8: 김재동

Sheet Input_disp_check
A1: T-support (외팔형) Input data & Displacement check sheet
B3: * 붉은 글씨만 입력.
B5: Material : | C5: SS275 | L5: <Note>
B6: Sy : | C6: 275 | D6: Mpa | E6: (AISC. Fy) | G6: Friction coefficient (H1) : | J6: 0.3 | L6: 1. 단면의 Shear deformation 효과는 무시함.
B7: Su : | C7: 410 | D7: Mpa | E7: (AISC. Fu) | G7: Notional load ratio(H2) : | J7: 0.2 | L7: 2. Support 철골의 자중은 무시함.
B8: E : | C8: 210000 | D8: Mpa | E8: (탄성계수) | L8: 3. 변위 기준점은 하중 작용점임. (단 H1에 의한 횡방향 변위는 Beam 의 축방향 변위가 미소하므로 기둥 상단부로 평가. )
B9: v : | C9: 0.3 | D9: (Poisson's ratio) | L9: 4. wind, seismic load 는 적용하지 않음. (Occasional load case 미고려)
B10: G : | C10: =C8/(2*(1+$C$9)) -> 80769.231 | D10: Mpa (전단탄성계수) | L10: 5. Load case : firction H1 과 notional load H2 는 동시에 작용하지 않음. H2 는 기둥 최상단에 작용.
B11: K : | C11: 2 | D11: (유효좌굴계수. Cantilever 2) | L11: operating case-1 : P+H1(friction)
L12: operating case-2 : P+H2(notional load)
L13: 6. Pipe 구속 방향의 변위(수직처짐) 한계는 배관 installation tolerance (1/16" = 1.5875mm) 감안하여 1/16"
L14: 7. Pipe 비구속 방향의 변위(횡변위) H/200
C35: <Input : X-Z Plan> | I35: <Operating case-1 : X-Z Plan displacement> | O35: <Operating case-2 : Y-Z Plan & X-Y Plan displacement>
B38: * table 추가 필요 시 table 최하단행 위로 행 삽입후 행 복사.
B39: H-형강
B40: NO. | C40: H (mm) | D40: MEMBER SIZE | F40: x (mm) | G40: L (mm) | H40: P (kg) | I40: P (N) | J40: H1 (Transe. , kg) | K40: H1 (Transe. , N) | L40: H2 (Longi. , kg) | M40: H2 (Longi. , N) | N40: Column moment (P) (major, N.mm) | O40: Column moment (H1) (major, N.mm) | P40: Column moment (P+H1) (major, N.mm) | Q40: Column moment (H2) (minor, N.mm) | R40: Beam moment (minor, N.mm) | S40: Case-1 Govern | U40: Case-2 Govern | W40: Disp. vertical limit (mm) | X40: Disp. horizontal limit (mm) | Y40: Result
S41: Disp. vertical d1 (mm) | T41: Disp. Hor. d2 (mm) | U41: Disp. Hor. d3 (mm) | V41: Disp. reference d_ref (mm)
B42: 1 | C42: 3000 | D42: H - | E42: 200 | F42: 600 | G42: 300 | H42: 2250 | I42: =H42*9.80665 -> 22064.962 | J42: =H42*$J$6 -> 675 | K42: =J42*9.80665 -> 6619.4887 | L42: =H42*$J$7 -> 450 | M42: =L42*9.80665 -> 4412.9925 | N42: =I42*G42 -> 6619488.7 | O42: =K42*C42 -> 19858466 | P42: =N42+O42 -> 26477955 | Q42: =M42*C42 -> 13238977 | S42: =(I42*G42^3/(3*$C$8*INDEX(profile_H!$J$6:$J$17, MATCH(E42, profile_H!$C$6:$C$17, 0)))) + (I42*C42/($C$8* INDEX(profile_H!$H$6:$H$17, MATCH(E42, profile_H!$C$6:$C$17, 0)))) + (SIN(N42*C42/($C$8*INDEX(profile_H!$J$6:$J$17, MATCH(E42, profile_H!$C$6:$C$17, 0))))*G42) + (SIN(K42*C42^2/(2*$C$8*INDEX(profile_H!$J$6:$J$17, MATCH(E42, profile_H!$C$6:$C$17, 0))))*G42) -> 1.5722575 | T42: =(N42*C42^2/(2*$C$8*INDEX(profile_H!$J$6:$J$17, MATCH(E42, profile_H!$C$6:$C$17, 0))))+ (K42*C42^3/(3*$C$8*INDEX(profile_H!$J$6:$J$17, MATCH(E42, profile_H!$C$6:$C$17, 0)))) -> 9.0156475 | V42: =M42*C42^3/(3*$C$8*INDEX(profile_H!$M$6:$M$17, MATCH(E42, profile_H!$C$6:$C$17, 0))) -> 11.820516 | W42: 1.5875 | X42: =C42/200 -> 15 | Y42: =IF(S42<=W42, IF(MAX(T42,V42)<=X42,"O.K","N.G"),"NG") -> O.K
B43: 2 | C43: 3000 | D43: H - | E43: 150 | F43: 600 | G43: 300 | H43: 800 | I43: =H43*9.80665 -> 7845.32 | J43: =H43*$J$6 -> 240 | K43: =J43*9.80665 -> 2353.596 | L43: =H43*$J$7 -> 160 | M43: =L43*9.80665 -> 1569.064 | N43: =I43*G43 -> 2353596 | O43: =K43*C43 -> 7060788 | P43: =N43+O43 -> 9414384 | Q43: =M43*C43 -> 4707192 | S43: =(I43*G43^3/(3*$C$8*INDEX(profile_H!$J$6:$J$17, MATCH(E43, profile_H!$C$6:$C$17, 0)))) + (I43*C43/($C$8* INDEX(profile_H!$H$6:$H$17, MATCH(E43, profile_H!$C$6:$C$17, 0)))) + (SIN(N43*C43/($C$8*INDEX(profile_H!$J$6:$J$17, MATCH(E43, profile_H!$C$6:$C$17, 0))))*G43) + (SIN(K43*C43^2/(2*$C$8*INDEX(profile_H!$J$6:$J$17, MATCH(E43, profile_H!$C$6:$C$17, 0))))*G43) -> 1.5860491 | T43: =(N43*C43^2/(2*$C$8*INDEX(profile_H!$J$6:$J$17, MATCH(E43, profile_H!$C$6:$C$17, 0))))+ (K43*C43^3/(3*$C$8*INDEX(profile_H!$J$6:$J$17, MATCH(E43, profile_H!$C$6:$C$17, 0)))) -> 9.2257683 | V43: =M43*C43^3/(3*$C$8*INDEX(profile_H!$M$6:$M$17, MATCH(E43, profile_H!$C$6:$C$17, 0))) -> 11.944156 | W43: 1.5875 | X43: =C43/200 -> 15 | Y43: =IF(S43<=W43, IF(MAX(T43,V43)<=X43,"O.K","N.G"),"NG") -> O.K
B44: 3 | C44: 3000 | D44: H - | E44: 125 | F44: 600 | G44: 300 | H44: 400 | I44: =H44*9.80665 -> 3922.66 | J44: =H44*$J$6 -> 120 | K44: =J44*9.80665 -> 1176.798 | L44: =H44*$J$7 -> 80 | M44: =L44*9.80665 -> 784.532 | N44: =I44*G44 -> 1176798 | O44: =K44*C44 -> 3530394 | P44: =N44+O44 -> 4707192 | Q44: =M44*C44 -> 2353596 | S44: =(I44*G44^3/(3*$C$8*INDEX(profile_H!$J$6:$J$17, MATCH(E44, profile_H!$C$6:$C$17, 0)))) + (I44*C44/($C$8* INDEX(profile_H!$H$6:$H$17, MATCH(E44, profile_H!$C$6:$C$17, 0)))) + (SIN(N44*C44/($C$8*INDEX(profile_H!$J$6:$J$17, MATCH(E44, profile_H!$C$6:$C$17, 0))))*G44) + (SIN(K44*C44^2/(2*$C$8*INDEX(profile_H!$J$6:$J$17, MATCH(E44, profile_H!$C$6:$C$17, 0))))*G44) -> 1.5269475 | T44: =(N44*C44^2/(2*$C$8*INDEX(profile_H!$J$6:$J$17, MATCH(E44, profile_H!$C$6:$C$17, 0))))+ (K44*C44^3/(3*$C$8*INDEX(profile_H!$J$6:$J$17, MATCH(E44, profile_H!$C$6:$C$17, 0)))) -> 8.9316765 | V44: =M44*C44^3/(3*$C$8*INDEX(profile_H!$M$6:$M$17, MATCH(E44, profile_H!$C$6:$C$17, 0))) -> 11.475358 | W44: 1.5875 | X44: =C44/200 -> 15 | Y44: =IF(S44<=W44, IF(MAX(T44,V44)<=X44,"O.K","N.G"),"NG") -> O.K
B45: 4 | C45: 2500 | D45: H - | E45: 200 | F45: 600 | G45: 300 | H45: 3000 | I45: =H45*9.80665 -> 29419.95 | J45: =H45*$J$6 -> 900 | K45: =J45*9.80665 -> 8825.985 | L45: =H45*$J$7 -> 600 | M45: =L45*9.80665 -> 5883.99 | N45: =I45*G45 -> 8825985 | O45: =K45*C45 -> 22064962 | P45: =N45+O45 -> 30890947 | Q45: =M45*C45 -> 14709975 | S45: =(I45*G45^3/(3*$C$8*INDEX(profile_H!$J$6:$J$17, MATCH(E45, profile_H!$C$6:$C$17, 0)))) + (I45*C45/($C$8* INDEX(profile_H!$H$6:$H$17, MATCH(E45, profile_H!$C$6:$C$17, 0)))) + (SIN(N45*C45/($C$8*INDEX(profile_H!$J$6:$J$17, MATCH(E45, profile_H!$C$6:$C$17, 0))))*G45) + (SIN(K45*C45^2/(2*$C$8*INDEX(profile_H!$J$6:$J$17, MATCH(E45, profile_H!$C$6:$C$17, 0))))*G45) -> 1.5844488 | T45: =(N45*C45^2/(2*$C$8*INDEX(profile_H!$J$6:$J$17, MATCH(E45, profile_H!$C$6:$C$17, 0))))+ (K45*C45^3/(3*$C$8*INDEX(profile_H!$J$6:$J$17, MATCH(E45, profile_H!$C$6:$C$17, 0)))) -> 7.420286 | V45: =M45*C45^3/(3*$C$8*INDEX(profile_H!$M$6:$M$17, MATCH(E45, profile_H!$C$6:$C$17, 0))) -> 9.1207682 | W45: 1.5875 | X45: =C45/200 -> 12.5 | Y45: =IF(S45<=W45, IF(MAX(T45,V45)<=X45,"O.K","N.G"),"NG") -> O.K
B46: 5 | C46: 2500 | D46: H - | E46: 150 | F46: 600 | G46: 300 | H46: 1050 | I46: =H46*9.80665 -> 10296.983 | J46: =H46*$J$6 -> 315 | K46: =J46*9.80665 -> 3089.0947 | L46: =H46*$J$7 -> 210 | M46: =L46*9.80665 -> 2059.3965 | N46: =I46*G46 -> 3089094.8 | O46: =K46*C46 -> 7722736.9 | P46: =N46+O46 -> 10811832 | Q46: =M46*C46 -> 5148491.2 | S46: =(I46*G46^3/(3*$C$8*INDEX(profile_H!$J$6:$J$17, MATCH(E46, profile_H!$C$6:$C$17, 0)))) + (I46*C46/($C$8* INDEX(profile_H!$H$6:$H$17, MATCH(E46, profile_H!$C$6:$C$17, 0)))) + (SIN(N46*C46/($C$8*INDEX(profile_H!$J$6:$J$17, MATCH(E46, profile_H!$C$6:$C$17, 0))))*G46) + (SIN(K46*C46^2/(2*$C$8*INDEX(profile_H!$J$6:$J$17, MATCH(E46, profile_H!$C$6:$C$17, 0))))*G46) -> 1.5710483 | T46: =(N46*C46^2/(2*$C$8*INDEX(profile_H!$J$6:$J$17, MATCH(E46, profile_H!$C$6:$C$17, 0))))+ (K46*C46^3/(3*$C$8*INDEX(profile_H!$J$6:$J$17, MATCH(E46, profile_H!$C$6:$C$17, 0)))) -> 7.4745808 | V46: =M46*C46^3/(3*$C$8*INDEX(profile_H!$M$6:$M$17, MATCH(E46, profile_H!$C$6:$C$17, 0))) -> 9.0721673 | W46: 1.5875 | X46: =C46/200 -> 12.5 | Y46: =IF(S46<=W46, IF(MAX(T46,V46)<=X46,"O.K","N.G"),"NG") -> O.K
B47: 6 | C47: 2500 | D47: H - | E47: 125 | F47: 600 | G47: 300 | H47: 550 | I47: =H47*9.80665 -> 5393.6575 | J47: =H47*$J$6 -> 165 | K47: =J47*9.80665 -> 1618.0972 | L47: =H47*$J$7 -> 110 | M47: =L47*9.80665 -> 1078.7315 | N47: =I47*G47 -> 1618097.2 | O47: =K47*C47 -> 4045243.1 | P47: =N47+O47 -> 5663340.4 | Q47: =M47*C47 -> 2696828.7 | S47: =(I47*G47^3/(3*$C$8*INDEX(profile_H!$J$6:$J$17, MATCH(E47, profile_H!$C$6:$C$17, 0)))) + (I47*C47/($C$8* INDEX(profile_H!$H$6:$H$17, MATCH(E47, profile_H!$C$6:$C$17, 0)))) + (SIN(N47*C47/($C$8*INDEX(profile_H!$J$6:$J$17, MATCH(E47, profile_H!$C$6:$C$17, 0))))*G47) + (SIN(K47*C47^2/(2*$C$8*INDEX(profile_H!$J$6:$J$17, MATCH(E47, profile_H!$C$6:$C$17, 0))))*G47) -> 1.5836059 | T47: =(N47*C47^2/(2*$C$8*INDEX(profile_H!$J$6:$J$17, MATCH(E47, profile_H!$C$6:$C$17, 0))))+ (K47*C47^3/(3*$C$8*INDEX(profile_H!$J$6:$J$17, MATCH(E47, profile_H!$C$6:$C$17, 0)))) -> 7.5808983 | V47: =M47*C47^3/(3*$C$8*INDEX(profile_H!$M$6:$M$17, MATCH(E47, profile_H!$C$6:$C$17, 0))) -> 9.1311445 | W47: 1.5875 | X47: =C47/200 -> 12.5 | Y47: =IF(S47<=W47, IF(MAX(T47,V47)<=X47,"O.K","N.G"),"NG") -> O.K
B48: 7 | C48: 2100 | D48: H - | E48: 200 | F48: 600 | G48: 300 | H48: 3850 | I48: =H48*9.80665 -> 37755.603 | J48: =H48*$J$6 -> 1155 | K48: =J48*9.80665 -> 11326.681 | L48: =H48*$J$7 -> 770 | M48: =L48*9.80665 -> 7551.1205 | N48: =I48*G48 -> 11326681 | O48: =K48*C48 -> 23786030 | P48: =N48+O48 -> 35112710 | Q48: =M48*C48 -> 15857353 | S48: =(I48*G48^3/(3*$C$8*INDEX(profile_H!$J$6:$J$17, MATCH(E48, profile_H!$C$6:$C$17, 0)))) + (I48*C48/($C$8* INDEX(profile_H!$H$6:$H$17, MATCH(E48, profile_H!$C$6:$C$17, 0)))) + (SIN(N48*C48/($C$8*INDEX(profile_H!$J$6:$J$17, MATCH(E48, profile_H!$C$6:$C$17, 0))))*G48) + (SIN(K48*C48^2/(2*$C$8*INDEX(profile_H!$J$6:$J$17, MATCH(E48, profile_H!$C$6:$C$17, 0))))*G48) -> 1.5695379 | T48: =(N48*C48^2/(2*$C$8*INDEX(profile_H!$J$6:$J$17, MATCH(E48, profile_H!$C$6:$C$17, 0))))+ (K48*C48^3/(3*$C$8*INDEX(profile_H!$J$6:$J$17, MATCH(E48, profile_H!$C$6:$C$17, 0)))) -> 6.0472957 | V48: =M48*C48^3/(3*$C$8*INDEX(profile_H!$M$6:$M$17, MATCH(E48, profile_H!$C$6:$C$17, 0))) -> 6.937592 | W48: 1.5875 | X48: =C48/200 -> 10.5 | Y48: =IF(S48<=W48, IF(MAX(T48,V48)<=X48,"O.K","N.G"),"NG") -> O.K
B49: 8 | C49: 2100 | D49: H - | E49: 150 | F49: 600 | G49: 300 | H49: 1350 | I49: =H49*9.80665 -> 13238.977 | J49: =H49*$J$6 -> 405 | K49: =J49*9.80665 -> 3971.6932 | L49: =H49*$J$7 -> 270 | M49: =L49*9.80665 -> 2647.7955 | N49: =I49*G49 -> 3971693.2 | O49: =K49*C49 -> 8340555.8 | P49: =N49+O49 -> 12312249 | Q49: =M49*C49 -> 5560370.5 | S49: =(I49*G49^3/(3*$C$8*INDEX(profile_H!$J$6:$J$17, MATCH(E49, profile_H!$C$6:$C$17, 0)))) + (I49*C49/($C$8* INDEX(profile_H!$H$6:$H$17, MATCH(E49, profile_H!$C$6:$C$17, 0)))) + (SIN(N49*C49/($C$8*INDEX(profile_H!$J$6:$J$17, MATCH(E49, profile_H!$C$6:$C$17, 0))))*G49) + (SIN(K49*C49^2/(2*$C$8*INDEX(profile_H!$J$6:$J$17, MATCH(E49, profile_H!$C$6:$C$17, 0))))*G49) -> 1.5569621 | T49: =(N49*C49^2/(2*$C$8*INDEX(profile_H!$J$6:$J$17, MATCH(E49, profile_H!$C$6:$C$17, 0))))+ (K49*C49^3/(3*$C$8*INDEX(profile_H!$J$6:$J$17, MATCH(E49, profile_H!$C$6:$C$17, 0)))) -> 6.1028457 | V49: =M49*C49^3/(3*$C$8*INDEX(profile_H!$M$6:$M$17, MATCH(E49, profile_H!$C$6:$C$17, 0))) -> 6.913427 | W49: 1.5875 | X49: =C49/200 -> 10.5 | Y49: =IF(S49<=W49, IF(MAX(T49,V49)<=X49,"O.K","N.G"),"NG") -> O.K
B50: 9 | C50: 2100 | D50: H - | E50: 125 | F50: 600 | G50: 300 | H50: 700 | I50: =H50*9.80665 -> 6864.655 | J50: =H50*$J$6 -> 210 | K50: =J50*9.80665 -> 2059.3965 | L50: =H50*$J$7 -> 140 | M50: =L50*9.80665 -> 1372.931 | N50: =I50*G50 -> 2059396.5 | O50: =K50*C50 -> 4324732.6 | P50: =N50+O50 -> 6384129.1 | Q50: =M50*C50 -> 2883155.1 | S50: =(I50*G50^3/(3*$C$8*INDEX(profile_H!$J$6:$J$17, MATCH(E50, profile_H!$C$6:$C$17, 0)))) + (I50*C50/($C$8* INDEX(profile_H!$H$6:$H$17, MATCH(E50, profile_H!$C$6:$C$17, 0)))) + (SIN(N50*C50/($C$8*INDEX(profile_H!$J$6:$J$17, MATCH(E50, profile_H!$C$6:$C$17, 0))))*G50) + (SIN(K50*C50^2/(2*$C$8*INDEX(profile_H!$J$6:$J$17, MATCH(E50, profile_H!$C$6:$C$17, 0))))*G50) -> 1.5526924 | T50: =(N50*C50^2/(2*$C$8*INDEX(profile_H!$J$6:$J$17, MATCH(E50, profile_H!$C$6:$C$17, 0))))+ (K50*C50^3/(3*$C$8*INDEX(profile_H!$J$6:$J$17, MATCH(E50, profile_H!$C$6:$C$17, 0)))) -> 6.1271301 | V50: =M50*C50^3/(3*$C$8*INDEX(profile_H!$M$6:$M$17, MATCH(E50, profile_H!$C$6:$C$17, 0))) -> 6.8880839 | W50: 1.5875 | X50: =C50/200 -> 10.5 | Y50: =IF(S50<=W50, IF(MAX(T50,V50)<=X50,"O.K","N.G"),"NG") -> O.K
B51: 10 | C51: 1500 | D51: H - | E51: 150 | F51: 600 | G51: 300 | H51: 2200 | I51: =H51*9.80665 -> 21574.63 | J51: =H51*$J$6 -> 660 | K51: =J51*9.80665 -> 6472.389 | L51: =H51*$J$7 -> 440 | M51: =L51*9.80665 -> 4314.926 | N51: =I51*G51 -> 6472389 | O51: =K51*C51 -> 9708583.5 | P51: =N51+O51 -> 16180972 | Q51: =M51*C51 -> 6472389 | S51: =(I51*G51^3/(3*$C$8*INDEX(profile_H!$J$6:$J$17, MATCH(E51, profile_H!$C$6:$C$17, 0)))) + (I51*C51/($C$8* INDEX(profile_H!$H$6:$H$17, MATCH(E51, profile_H!$C$6:$C$17, 0)))) + (SIN(N51*C51/($C$8*INDEX(profile_H!$J$6:$J$17, MATCH(E51, profile_H!$C$6:$C$17, 0))))*G51) + (SIN(K51*C51^2/(2*$C$8*INDEX(profile_H!$J$6:$J$17, MATCH(E51, profile_H!$C$6:$C$17, 0))))*G51) -> 1.5747369 | T51: =(N51*C51^2/(2*$C$8*INDEX(profile_H!$J$6:$J$17, MATCH(E51, profile_H!$C$6:$C$17, 0))))+ (K51*C51^3/(3*$C$8*INDEX(profile_H!$J$6:$J$17, MATCH(E51, profile_H!$C$6:$C$17, 0)))) -> 4.2284771 | V51: =M51*C51^3/(3*$C$8*INDEX(profile_H!$M$6:$M$17, MATCH(E51, profile_H!$C$6:$C$17, 0))) -> 4.1058037 | W51: 1.5875 | X51: =C51/200 -> 7.5 | Y51: =IF(S51<=W51, IF(MAX(T51,V51)<=X51,"O.K","N.G"),"NG") -> O.K
B52: 11 | C52: 1500 | D52: H - | E52: 125 | F52: 600 | G52: 300 | H52: 1150 | I52: =H52*9.80665 -> 11277.647 | J52: =H52*$J$6 -> 345 | K52: =J52*9.80665 -> 3383.2942 | L52: =H52*$J$7 -> 230 | M52: =L52*9.80665 -> 2255.5295 | N52: =I52*G52 -> 3383294.2 | O52: =K52*C52 -> 5074941.4 | P52: =N52+O52 -> 8458235.6 | Q52: =M52*C52 -> 3383294.2 | S52: =(I52*G52^3/(3*$C$8*INDEX(profile_H!$J$6:$J$17, MATCH(E52, profile_H!$C$6:$C$17, 0)))) + (I52*C52/($C$8* INDEX(profile_H!$H$6:$H$17, MATCH(E52, profile_H!$C$6:$C$17, 0)))) + (SIN(N52*C52/($C$8*INDEX(profile_H!$J$6:$J$17, MATCH(E52, profile_H!$C$6:$C$17, 0))))*G52) + (SIN(K52*C52^2/(2*$C$8*INDEX(profile_H!$J$6:$J$17, MATCH(E52, profile_H!$C$6:$C$17, 0))))*G52) -> 1.5815553 | T52: =(N52*C52^2/(2*$C$8*INDEX(profile_H!$J$6:$J$17, MATCH(E52, profile_H!$C$6:$C$17, 0))))+ (K52*C52^3/(3*$C$8*INDEX(profile_H!$J$6:$J$17, MATCH(E52, profile_H!$C$6:$C$17, 0)))) -> 4.2797617 | V52: =M52*C52^3/(3*$C$8*INDEX(profile_H!$M$6:$M$17, MATCH(E52, profile_H!$C$6:$C$17, 0))) -> 4.1239569 | W52: 1.5875 | X52: =C52/200 -> 7.5 | Y52: =IF(S52<=W52, IF(MAX(T52,V52)<=X52,"O.K","N.G"),"NG") -> O.K
B53: 12 | C53: 1000 | D53: H - | E53: 150 | F53: 600 | G53: 300 | H53: 3200 | I53: =H53*9.80665 -> 31381.28 | J53: =H53*$J$6 -> 960 | K53: =J53*9.80665 -> 9414.384 | L53: =H53*$J$7 -> 640 | M53: =L53*9.80665 -> 6276.256 | N53: =I53*G53 -> 9414384 | O53: =K53*C53 -> 9414384 | P53: =N53+O53 -> 18828768 | Q53: =M53*C53 -> 6276256 | S53: =(I53*G53^3/(3*$C$8*INDEX(profile_H!$J$6:$J$17, MATCH(E53, profile_H!$C$6:$C$17, 0)))) + (I53*C53/($C$8* INDEX(profile_H!$H$6:$H$17, MATCH(E53, profile_H!$C$6:$C$17, 0)))) + (SIN(N53*C53/($C$8*INDEX(profile_H!$J$6:$J$17, MATCH(E53, profile_H!$C$6:$C$17, 0))))*G53) + (SIN(K53*C53^2/(2*$C$8*INDEX(profile_H!$J$6:$J$17, MATCH(E53, profile_H!$C$6:$C$17, 0))))*G53) -> 1.3493365 | T53: =(N53*C53^2/(2*$C$8*INDEX(profile_H!$J$6:$J$17, MATCH(E53, profile_H!$C$6:$C$17, 0))))+ (K53*C53^3/(3*$C$8*INDEX(profile_H!$J$6:$J$17, MATCH(E53, profile_H!$C$6:$C$17, 0)))) -> 2.2779675 | V53: =M53*C53^3/(3*$C$8*INDEX(profile_H!$M$6:$M$17, MATCH(E53, profile_H!$C$6:$C$17, 0))) -> 1.7695046 | W53: 1.5875 | X53: =C53/200 -> 5 | Y53: =IF(S53<=W53, IF(MAX(T53,V53)<=X53,"O.K","N.G"),"NG") -> O.K | AA53: Stress govern
B54: 13 | C54: 1000 | D54: H - | E54: 125 | F54: 600 | G54: 300 | H54: 1950 | I54: =H54*9.80665 -> 19122.967 | J54: =H54*$J$6 -> 585 | K54: =J54*9.80665 -> 5736.8902 | L54: =H54*$J$7 -> 390 | M54: =L54*9.80665 -> 3824.5935 | N54: =I54*G54 -> 5736890.2 | O54: =K54*C54 -> 5736890.2 | P54: =N54+O54 -> 11473780 | Q54: =M54*C54 -> 3824593.5 | S54: =(I54*G54^3/(3*$C$8*INDEX(profile_H!$J$6:$J$17, MATCH(E54, profile_H!$C$6:$C$17, 0)))) + (I54*C54/($C$8* INDEX(profile_H!$H$6:$H$17, MATCH(E54, profile_H!$C$6:$C$17, 0)))) + (SIN(N54*C54/($C$8*INDEX(profile_H!$J$6:$J$17, MATCH(E54, profile_H!$C$6:$C$17, 0))))*G54) + (SIN(K54*C54^2/(2*$C$8*INDEX(profile_H!$J$6:$J$17, MATCH(E54, profile_H!$C$6:$C$17, 0))))*G54) -> 1.5781988 | T54: =(N54*C54^2/(2*$C$8*INDEX(profile_H!$J$6:$J$17, MATCH(E54, profile_H!$C$6:$C$17, 0))))+ (K54*C54^3/(3*$C$8*INDEX(profile_H!$J$6:$J$17, MATCH(E54, profile_H!$C$6:$C$17, 0)))) -> 2.687773 | V54: =M54*C54^3/(3*$C$8*INDEX(profile_H!$M$6:$M$17, MATCH(E54, profile_H!$C$6:$C$17, 0))) -> 2.0719397 | W54: 1.5875 | X54: =C54/200 -> 5 | Y54: =IF(S54<=W54, IF(MAX(T54,V54)<=X54,"O.K","N.G"),"NG") -> O.K
B55: 14 | C55: 500 | D55: H - | E55: 150 | F55: 600 | G55: 300 | H55: 4500 | I55: =H55*9.80665 -> 44129.925 | J55: =H55*$J$6 -> 1350 | K55: =J55*9.80665 -> 13238.977 | L55: =H55*$J$7 -> 900 | M55: =L55*9.80665 -> 8825.985 | N55: =I55*G55 -> 13238977 | O55: =K55*C55 -> 6619488.7 | P55: =N55+O55 -> 19858466 | Q55: =M55*C55 -> 4412992.5 | S55: =(I55*G55^3/(3*$C$8*INDEX(profile_H!$J$6:$J$17, MATCH(E55, profile_H!$C$6:$C$17, 0)))) + (I55*C55/($C$8* INDEX(profile_H!$H$6:$H$17, MATCH(E55, profile_H!$C$6:$C$17, 0)))) + (SIN(N55*C55/($C$8*INDEX(profile_H!$J$6:$J$17, MATCH(E55, profile_H!$C$6:$C$17, 0))))*G55) + (SIN(K55*C55^2/(2*$C$8*INDEX(profile_H!$J$6:$J$17, MATCH(E55, profile_H!$C$6:$C$17, 0))))*G55) -> 0.86226109 | T55: =(N55*C55^2/(2*$C$8*INDEX(profile_H!$J$6:$J$17, MATCH(E55, profile_H!$C$6:$C$17, 0))))+ (K55*C55^3/(3*$C$8*INDEX(profile_H!$J$6:$J$17, MATCH(E55, profile_H!$C$6:$C$17, 0)))) -> 0.64067835 | V55: =M55*C55^3/(3*$C$8*INDEX(profile_H!$M$6:$M$17, MATCH(E55, profile_H!$C$6:$C$17, 0))) -> 0.31104574 | W55: 1.5875 | X55: =C55/200 -> 2.5 | Y55: =IF(S55<=W55, IF(MAX(T55,V55)<=X55,"O.K","N.G"),"NG") -> O.K | AA55: Stress govern
B56: 15 | C56: 500 | D56: H - | E56: 125 | F56: 600 | G56: 300 | H56: 2900 | I56: =H56*9.80665 -> 28439.285 | J56: =H56*$J$6 -> 870 | K56: =J56*9.80665 -> 8531.7855 | L56: =H56*$J$7 -> 580 | M56: =L56*9.80665 -> 5687.857 | N56: =I56*G56 -> 8531785.5 | O56: =K56*C56 -> 4265892.8 | P56: =N56+O56 -> 12797678 | Q56: =M56*C56 -> 2843928.5 | S56: =(I56*G56^3/(3*$C$8*INDEX(profile_H!$J$6:$J$17, MATCH(E56, profile_H!$C$6:$C$17, 0)))) + (I56*C56/($C$8* INDEX(profile_H!$H$6:$H$17, MATCH(E56, profile_H!$C$6:$C$17, 0)))) + (SIN(N56*C56/($C$8*INDEX(profile_H!$J$6:$J$17, MATCH(E56, profile_H!$C$6:$C$17, 0))))*G56) + (SIN(K56*C56^2/(2*$C$8*INDEX(profile_H!$J$6:$J$17, MATCH(E56, profile_H!$C$6:$C$17, 0))))*G56) -> 1.0656088 | T56: =(N56*C56^2/(2*$C$8*INDEX(profile_H!$J$6:$J$17, MATCH(E56, profile_H!$C$6:$C$17, 0))))+ (K56*C56^3/(3*$C$8*INDEX(profile_H!$J$6:$J$17, MATCH(E56, profile_H!$C$6:$C$17, 0)))) -> 0.79944018 | V56: =M56*C56^3/(3*$C$8*INDEX(profile_H!$M$6:$M$17, MATCH(E56, profile_H!$C$6:$C$17, 0))) -> 0.38516828 | W56: 1.5875 | X56: =C56/200 -> 2.5 | Y56: =IF(S56<=W56, IF(MAX(T56,V56)<=X56,"O.K","N.G"),"NG") -> O.K | AA56: Stress govern
B61: * table 추가 필요 시 table 최하단행 위로 행 삽입후 행 복사.
B62: Channel
B63: NO. | C63: H (mm) | D63: MEMBER SIZE | F63: x (mm) | G63: L (mm) | H63: P (kg) | I63: P (N) | J63: H1 (Transe. , kg) | K63: H1 (Transe. , N) | L63: H2 (Longi. , kg) | M63: H2 (Longi. , N) | N63: Column moment (P) (major, N.mm) | O63: Column moment (H1) (major, N.mm) | P63: Column moment (P+H1) (major, N.mm) | Q63: Column moment (H2) (minor, N.mm) | R63: Beam moment (minor, N.mm) | S63: Case-1 Govern | U63: Case-2 Govern | W63: Disp. vertical limit (mm) | X63: Disp. horizontal limit (mm) | Y63: Result
S64: Disp. vertical d1 (mm) | T64: Disp. Hor. d2 (mm) | U64: Disp. Hor. d3 (mm) | V64: Disp. reference d_ref (mm)
B65: 1 | C65: 3000 | D65: C - | E65: 200 | F65: 600 | G65: 300 | H65: 450 | I65: =H65*9.80665 -> 4412.9925 | J65: =H65*$J$6 -> 135 | K65: =J65*9.80665 -> 1323.8977 | L65: =H65*$J$7 -> 90 | M65: =L65*9.80665 -> 882.5985 | N65: =I65*G65 -> 1323897.7 | O65: =K65*C65 -> 3971693.2 | P65: =N65+O65 -> 5295591 | Q65: =M65*C65 -> 2647795.5 | S65: =(I65*G65^3/(3*$C$8*INDEX(profile_C!$J$6:$J$20, MATCH(E65, profile_C!$C$6:$C$20, 0)))) + (I65*C65/($C$8* INDEX(profile_C!$H$6:$H$20, MATCH(E65, profile_C!$C$6:$C$20, 0)))) + (SIN(N65*C65/($C$8*INDEX(profile_C!$J$6:$J$20, MATCH(E65, profile_C!$C$6:$C$20, 0))))*G65) + (SIN(K65*C65^2/(2*$C$8*INDEX(profile_C!$J$6:$J$20, MATCH(E65, profile_C!$C$6:$C$20, 0))))*G65) -> 0.59357001 | T65: =(N65*C65^2/(2*$C$8*INDEX(profile_C!$J$6:$J$20, MATCH(E65, profile_C!$C$6:$C$20, 0))))+ (K65*C65^3/(3*$C$8*INDEX(profile_C!$J$6:$J$20, MATCH(E65, profile_C!$C$6:$C$20, 0)))) -> 3.4179804 | V65: =M65*C65^3/(3*$C$8*INDEX(profile_C!$M$6:$M$20, MATCH(E65, profile_C!$C$6:$C$20, 0))) -> 13.655469 | W65: 1.5875 | X65: =C65/200 -> 15 | Y65: =IF(S65<=W65, IF(MAX(T65,V65)<=X65,"O.K","N.G"),"NG") -> O.K
B66: 2 | C66: 2500 | D66: C - | E66: 200 | F66: 600 | G66: 300 | H66: 700 | I66: =H66*9.80665 -> 6864.655 | J66: =H66*$J$6 -> 210 | K66: =J66*9.80665 -> 2059.3965 | L66: =H66*$J$7 -> 140 | M66: =L66*9.80665 -> 1372.931 | N66: =I66*G66 -> 2059396.5 | O66: =K66*C66 -> 5148491.2 | P66: =N66+O66 -> 7207887.8 | Q66: =M66*C66 -> 3432327.5 | S66: =(I66*G66^3/(3*$C$8*INDEX(profile_C!$J$6:$J$20, MATCH(E66, profile_C!$C$6:$C$20, 0)))) + (I66*C66/($C$8* INDEX(profile_C!$H$6:$H$20, MATCH(E66, profile_C!$C$6:$C$20, 0)))) + (SIN(N66*C66/($C$8*INDEX(profile_C!$J$6:$J$20, MATCH(E66, profile_C!$C$6:$C$20, 0))))*G66) + (SIN(K66*C66^2/(2*$C$8*INDEX(profile_C!$J$6:$J$20, MATCH(E66, profile_C!$C$6:$C$20, 0))))*G66) -> 0.69756654 | T66: =(N66*C66^2/(2*$C$8*INDEX(profile_C!$J$6:$J$20, MATCH(E66, profile_C!$C$6:$C$20, 0))))+ (K66*C66^3/(3*$C$8*INDEX(profile_C!$J$6:$J$20, MATCH(E66, profile_C!$C$6:$C$20, 0)))) -> 3.2820114 | V66: =M66*C66^3/(3*$C$8*INDEX(profile_C!$M$6:$M$20, MATCH(E66, profile_C!$C$6:$C$20, 0))) -> 12.292732 | W66: 1.5875 | X66: =C66/200 -> 12.5 | Y66: =IF(S66<=W66, IF(MAX(T66,V66)<=X66,"O.K","N.G"),"NG") -> O.K
B67: 3 | C67: 2100 | D67: C - | E67: 150 | F67: 600 | G67: 300 | H67: 400 | I67: =H67*9.80665 -> 3922.66 | J67: =H67*$J$6 -> 120 | K67: =J67*9.80665 -> 1176.798 | L67: =H67*$J$7 -> 80 | M67: =L67*9.80665 -> 784.532 | N67: =I67*G67 -> 1176798 | O67: =K67*C67 -> 2471275.8 | P67: =N67+O67 -> 3648073.8 | Q67: =M67*C67 -> 1647517.2 | S67: =(I67*G67^3/(3*$C$8*INDEX(profile_C!$J$6:$J$20, MATCH(E67, profile_C!$C$6:$C$20, 0)))) + (I67*C67/($C$8* INDEX(profile_C!$H$6:$H$20, MATCH(E67, profile_C!$C$6:$C$20, 0)))) + (SIN(N67*C67/($C$8*INDEX(profile_C!$J$6:$J$20, MATCH(E67, profile_C!$C$6:$C$20, 0))))*G67) + (SIN(K67*C67^2/(2*$C$8*INDEX(profile_C!$J$6:$J$20, MATCH(E67, profile_C!$C$6:$C$20, 0))))*G67) -> 0.87663949 | T67: =(N67*C67^2/(2*$C$8*INDEX(profile_C!$J$6:$J$20, MATCH(E67, profile_C!$C$6:$C$20, 0))))+ (K67*C67^3/(3*$C$8*INDEX(profile_C!$J$6:$J$20, MATCH(E67, profile_C!$C$6:$C$20, 0)))) -> 3.4442868 | V67: =M67*C67^3/(3*$C$8*INDEX(profile_C!$M$6:$M$20, MATCH(E67, profile_C!$C$6:$C$20, 0))) -> 9.8569405 | W67: 1.5875 | X67: =C67/200 -> 10.5 | Y67: =IF(S67<=W67, IF(MAX(T67,V67)<=X67,"O.K","N.G"),"NG") -> O.K
B68: 4 | C68: 1900 | D68: C - | E68: 125 | F68: 600 | G68: 300 | H68: 250 | I68: =H68*9.80665 -> 2451.6625 | J68: =H68*$J$6 -> 75 | K68: =J68*9.80665 -> 735.49875 | L68: =H68*$J$7 -> 50 | M68: =L68*9.80665 -> 490.3325 | N68: =I68*G68 -> 735498.75 | O68: =K68*C68 -> 1397447.6 | P68: =N68+O68 -> 2132946.4 | Q68: =M68*C68 -> 931631.75 | S68: =(I68*G68^3/(3*$C$8*INDEX(profile_C!$J$6:$J$20, MATCH(E68, profile_C!$C$6:$C$20, 0)))) + (I68*C68/($C$8* INDEX(profile_C!$H$6:$H$20, MATCH(E68, profile_C!$C$6:$C$20, 0)))) + (SIN(N68*C68/($C$8*INDEX(profile_C!$J$6:$J$20, MATCH(E68, profile_C!$C$6:$C$20, 0))))*G68) + (SIN(K68*C68^2/(2*$C$8*INDEX(profile_C!$J$6:$J$20, MATCH(E68, profile_C!$C$6:$C$20, 0))))*G68) -> 0.95587916 | T68: =(N68*C68^2/(2*$C$8*INDEX(profile_C!$J$6:$J$20, MATCH(E68, profile_C!$C$6:$C$20, 0))))+ (K68*C68^3/(3*$C$8*INDEX(profile_C!$J$6:$J$20, MATCH(E68, profile_C!$C$6:$C$20, 0)))) -> 3.3795716 | V68: =M68*C68^3/(3*$C$8*INDEX(profile_C!$M$6:$M$20, MATCH(E68, profile_C!$C$6:$C$20, 0))) -> 8.6381842 | W68: 1.5875 | X68: =C68/200 -> 9.5 | Y68: =IF(S68<=W68, IF(MAX(T68,V68)<=X68,"O.K","N.G"),"NG") -> O.K
...

Sheet Stress_check
B1: T-support (외팔형) Stress check (ASME BPVC.III.1.NF-2025, NF 3300)
B4: * 붉은 글씨만 입력.
B5: * table 추가 필요 시 table 최하단행 위로 행 삽입후 행 복사. "Input_disp_check" tab 과 No. 일치해야 함.
C6: Code Equation No. | D6: ASME BPVC.III.1.NF-2025, NF 3300 | T6: (17) | U6: (17),(18) | V6: (19) | W6: (9) | X6: (17) | Y6: (18) | Z6: (19) | AE6: (14) | AJ6: (20) | AK6: (21) | AL6: (22) | AO6: (20) | AP6: (21) | AQ6: (22)
D7: AISC : ADS 89 (steel construction manual 9th) | W7: F1-1 | X7: F1-6 | Y7: F1-7 | Z7: F1-8 | AE7: F2-1 | AJ7: H1-1 | AK7: H1-2 | AL7: H1-3 | AO7: H1-1 | AP7: H1-2 | AQ7: H1-3
B9: H 형강
B10: NO. | C10: 높이 (mm) | D10: MEMBER SIZE | F10: Compression : Column | N10: Flexural : Column major axis | AE10: Flexural - Column minor axis | AG10: Combined stress : Columl axial compression + bending | AT10: Shear : Beam
AG11: Common | AJ11: Load Case1 : Vertical + Longi. Friction | AO11: Load Case2: Vertical + Transe. Friction | AT11: Major axis
F12: Cc | G12: K | H12: KL/r 세장비 (λ) | J12: Fa1 (Mpa) | K12: Fa2 (Mpa) | L12: Fa (Mpa) | M12: fa (Mpa) | N12: fa/Sy (0.16) 판정 | O12: Lc1 (mm) | P12: Lc2 (mm) | Q12: Lc (mm) | R12: rc (mm) | S12: l/rc | T12: 횡좌굴 기준1 | U12: 횡좌굴 기준2 | V12: Cb | W12: Fb1 (Mpa) | X12: Fb2-1 (Mpa) | Y12: Fb2-2 (Mpa) | Z12: Fb2-3 (Mpa) | AA12: Fb2 (Mpa) | AB12: Fb (Mpa) | AC12: fb1 (Mpa) | AD12: fb2 (Mpa) | AE12: Fb-minor (Mpa) | AF12: fb-minor (Mpa) | AG12: F'e (Mpa) | AH12: F'e - Minor (Mpa) | AI12: Cm | AJ12: Ratio 1 | AK12: Ratio 2 | AL12: Ratio 3 | AM12: Stress ratio | AN12: Result | AO12: Ratio 1 | AP12: Ratio 2 | AQ12: Ratio 3 | AR12: Stress ratio | AS12: Result | AT12: Fv (Mpa) | AU12: fv (Mpa) | AV12: Stress ratio | AW12: Result
X13: Lb > Lc 인 경우
B14: 1 | C14: =(INDEX(Input_disp_check!$C$42:$C$58, MATCH(B14,Input_disp_check!$B$42:$B$58,0))) -> 3000 | D14: =(INDEX(Input_disp_check!$D$42:$D$58, MATCH(B14,Input_disp_check!$B$42:$B$58,0))) -> H - | E14: =(INDEX(Input_disp_check!$E$42:$E$58, MATCH(B14,Input_disp_check!$B$42:$B$58,0))) -> 200 | F14: =SQRT(2*PI()^2*Input_disp_check!$C$8/Input_disp_check!$C$6) -> 122.7745 | G14: 2 | H14: =G14*C14/(INDEX(profile_H!$O$6:$O$17, MATCH(E14, profile_H!$C$6:$C$17, 0))) -> 119.52191 | I14: =IF(H14>200, "N.G","OK") -> OK | J14: =12*PI()^2*Input_disp_check!$C$8/(23*H14^2) -> 75.696776 | K14: =(1-H14^2/(2*F14^2))*Input_disp_check!$C$6 / ((5/3) + (3*H14/(8*F14))-(H14^3/(8*F14^3))) -> 75.500135 | L14: =IF(H14<F14,K14,J14) -> 75.500135 | M14: =(INDEX(Input_disp_check!$I$42:$I$58, MATCH(B14,Input_disp_check!$B$42:$B$58,0)))/(INDEX(profile_H!$H$6:$H$17, MATCH(E14, profile_H!$C$6:$C$17, 0))) -> 3.4731564 | N14: =IF(M14/Input_disp_check!$C$6<=0.16,"OK","Warning") -> OK | O14: =200*(INDEX(profile_H!$D$6:$D$17, MATCH(E14, profile_H!$C$6:$C$17, 0)))/SQRT(Input_disp_check!$C$6) -> 2412.0908 | P14: =138000/(E14/((INDEX(profile_H!$D$6:$D$17, MATCH(E14, profile_H!$C$6:$C$17, 0)))*(INDEX(profile_H!$F$6:$F$17, MATCH(E14, profile_H!$C$6:$C$17, 0))))*Input_disp_check!$C$6) -> 6021.8182 | Q14: =MIN(O14:P14) -> 2412.0908 | R14: =INDEX(profile_H!$I$6:$I$17, MATCH(E14, profile_H!$C$6:$C$17, 0)) -> 55.108187 | S14: =(C14)/R14 -> 54.438372 | T14: =(703.3*1000*V14/Input_disp_check!$C$6)^0.5 -> 50.571282 | U14: =(3516*1000*V14/Input_disp_check!$C$6)^0.5 -> 113.07278 | V14: 1 | W14: =MIN(0.66*Input_disp_check!$C$6, 0.55*Input_disp_check!$C$7) -> 181.5 | X14: =MIN(((2/3)-(Input_disp_check!$C$6*(C14/R14)^2 / (10550 * 1000*V14))),0.6) * Input_disp_check!$C$6 -> 162.08997 | Y14: =MIN((1172*1000*V14)/(C14/R14)^2, 0.6*Input_disp_check!$C$6) -> 165 | Z14: =MIN((82740*V14)/(C14*E14/INDEX(profile_H!$U$6:$U$17, MATCH(E14, profile_H!$C$6:$C$17, 0))), 0.6*Input_disp_check!$C$6) -> 165 | AA14: =MAX(IF(S14>=T14,IF(S14<=U14,X14,Y14), Z14),Z14) -> 165 | AB14: =IF(C14>Q14,AA14,W14) -> 165 | AC14: =(INDEX(Input_disp_check!$P$42:$P$58, MATCH(B14,Input_disp_check!$B$42:$B$58,0)))/INDEX(profile_H!$K$6:$K$17,MATCH(E14, profile_H!$C$6:$C$17, 0)) -> 56.097362 | AD14: =(INDEX(Input_disp_check!$N$42:$N$58, MATCH(B14,Input_disp_check!$B$42:$B$58,0)))/INDEX(profile_H!$K$6:$K$17,MATCH(E14, profile_H!$C$6:$C$17, 0)) -> 14.024341 | AE14: =MIN(0.75*Input_disp_check!$C$6,0.63*Input_disp_check!$C$7) -> 206.25 | AF14: =(INDEX(Input_disp_check!$Q$42:$Q$58, MATCH(B14,Input_disp_check!$B$42:$B$58,0)))/INDEX(profile_H!$N$6:$N$17, MATCH(E14, profile_H!$C$6:$C$17, 0)) -> 82.743609 | AG14: =12*PI()^2*Input_disp_check!$C$8/(23*(G14*C14/INDEX(profile_H!$L$6:$L$17, MATCH(E14, profile_H!$C$6:$C$17, 0)))^2) -> 223.19501 | AH14: =12*PI()^2*Input_disp_check!$C$8/(23*(G14*C14/INDEX(profile_H!$O$6:$O$17, MATCH(E14, profile_H!$C$6:$C$17, 0)))^2) -> 75.696776 | AI14: 0.85 | AJ14: =(M14/L14)+(AI14*AD14/((1-M14/AG14)*AB14))+(AI14*AF14/((1-M14/AH14)*AE14)) -> 0.47679308 | AK14: =(M14/(0.6*Input_disp_check!$C$6))+(AD14/AB14)+(AF14/AE14) -> 0.50722657 | AL14: =(M14/L14)+(AD14/AB14)+(AF14/AE14) -> 0.53217913 | AM14: =IF(M14/L14<=0.15,AL14,MAX(AJ14,AK14)) -> 0.53217913 | AN14: =IF(AM14<=1,"OK","NG") -> OK | AO14: =(M14/L14)+(AI14*AC14/((1-M14/AG14)*AB14)) -> 0.33955643 | AP14: =(M14/(0.6*Input_disp_check!$C$6))+(AC14/AB14) -> 0.36103345 | AQ14: =(M14/L14)+(AC14/AB14) -> 0.385986 | AR14: =IF(M14/L14<=0.15,AQ14,MAX(AO14,AP14)) -> 0.385986 | AS14: =IF(AR14<=1,"OK","NG") -> OK | AT14: =MIN(0.4*Input_disp_check!$C$6,0.33*Input_disp_check!$C$7) -> 110 | AU14: =(INDEX(Input_disp_check!$I$42:$I$58, MATCH(B14,Input_disp_check!$B$42:$B$58,0)))/INDEX(profile_H!$T$6:$T$17, MATCH(E14, profile_H!$C$6:$C$17, 0)) -> 13.790602 | AV14: =AU14/AT14 -> 0.12536911 | AW14: =IF(AV14<=1,"OK","NG") -> OK
B15: 2 | C15: =(INDEX(Input_disp_check!$C$42:$C$58, MATCH(B15,Input_disp_check!$B$42:$B$58,0))) -> 3000 | D15: =(INDEX(Input_disp_check!$D$42:$D$58, MATCH(B15,Input_disp_check!$B$42:$B$58,0))) -> H - | E15: =(INDEX(Input_disp_check!$E$42:$E$58, MATCH(B15,Input_disp_check!$B$42:$B$58,0))) -> 150 | F15: =SQRT(2*PI()^2*Input_disp_check!$C$8/Input_disp_check!$C$6) -> 122.7745 | G15: 2 | H15: =G15*C15/(INDEX(profile_H!$O$6:$O$17, MATCH(E15, profile_H!$C$6:$C$17, 0))) -> 160 | I15: =IF(H15>200, "N.G","OK") -> OK | J15: =12*PI()^2*Input_disp_check!$C$8/(23*H15^2) -> 42.240834 | K15: =(1-H15^2/(2*F15^2))*Input_disp_check!$C$6 / ((5/3) + (3*H15/(8*F15))-(H15^3/(8*F15^3))) -> 22.078361 | L15: =IF(H15<F15,K15,J15) -> 42.240834 | M15: =(INDEX(Input_disp_check!$I$42:$I$58, MATCH(B15,Input_disp_check!$B$42:$B$58,0)))/(INDEX(profile_H!$H$6:$H$17, MATCH(E15, profile_H!$C$6:$C$17, 0))) -> 1.9544893 | N15: =IF(M15/Input_disp_check!$C$6<=0.16,"OK","Warning") -> OK | O15: =200*(INDEX(profile_H!$D$6:$D$17, MATCH(E15, profile_H!$C$6:$C$17, 0)))/SQRT(Input_disp_check!$C$6) -> 1809.0681 | P15: =138000/(E15/((INDEX(profile_H!$D$6:$D$17, MATCH(E15, profile_H!$C$6:$C$17, 0)))*(INDEX(profile_H!$F$6:$F$17, MATCH(E15, profile_H!$C$6:$C$17, 0))))*Input_disp_check!$C$6) -> 5018.1818 | Q15: =MIN(O15:P15) -> 1809.0681 | R15: =INDEX(profile_H!$I$6:$I$17, MATCH(E15, profile_H!$C$6:$C$17, 0)) -> 41.269848 | S15: =(C15)/R15 -> 72.692295 | T15: =(703.3*1000*V15/Input_disp_check!$C$6)^0.5 -> 50.571282 | U15: =(3516*1000*V15/Input_disp_check!$C$6)^0.5 -> 113.07278 | V15: 1 | W15: =MIN(0.66*Input_disp_check!$C$6, 0.55*Input_disp_check!$C$7) -> 181.5 | X15: =MIN(((2/3)-(Input_disp_check!$C$6*(C15/R15)^2 / (10550 * 1000*V15))),0.6) * Input_disp_check!$C$6 -> 145.4551 | Y15: =MIN((1172*1000*V15)/(C15/R15)^2, 0.6*Input_disp_check!$C$6) -> 165 | Z15: =MIN((82740*V15)/(C15*E15/INDEX(profile_H!$U$6:$U$17, MATCH(E15, profile_H!$C$6:$C$17, 0))), 0.6*Input_disp_check!$C$6) -> 165 | AA15: =MAX(IF(S15>=T15,IF(S15<=U15,X15,Y15), Z15),Z15) -> 165 | AB15: =IF(C15>Q15,AA15,W15) -> 165 | AC15: =(INDEX(Input_disp_check!$P$42:$P$58, MATCH(B15,Input_disp_check!$B$42:$B$58,0)))/INDEX(profile_H!$K$6:$K$17,MATCH(E15, profile_H!$C$6:$C$17, 0)) -> 42.988055 | AD15: =(INDEX(Input_disp_check!$N$42:$N$58, MATCH(B15,Input_disp_check!$B$42:$B$58,0)))/INDEX(profile_H!$K$6:$K$17,MATCH(E15, profile_H!$C$6:$C$17, 0)) -> 10.747014 | AE15: =MIN(0.75*Input_disp_check!$C$6,0.63*Input_disp_check!$C$7) -> 206.25 | AF15: =(INDEX(Input_disp_check!$Q$42:$Q$58, MATCH(B15,Input_disp_check!$B$42:$B$58,0)))/INDEX(profile_H!$N$6:$N$17, MATCH(E15, profile_H!$C$6:$C$17, 0)) -> 62.678988 | AG15: =12*PI()^2*Input_disp_check!$C$8/(23*(G15*C15/INDEX(profile_H!$L$6:$L$17, MATCH(E15, profile_H!$C$6:$C$17, 0)))^2) -> 122.65116 | AH15: =12*PI()^2*Input_disp_check!$C$8/(23*(G15*C15/INDEX(profile_H!$O$6:$O$17, MATCH(E15, profile_H!$C$6:$C$17, 0)))^2) -> 42.240834 | AI15: 0.85 | AJ15: =(M15/L15)+(AI15*AD15/((1-M15/AG15)*AB15))+(AI15*AF15/((1-M15/AH15)*AE15)) -> 0.37337553 | AK15: =(M15/(0.6*Input_disp_check!$C$6))+(AD15/AB15)+(AF15/AE15) -> 0.38087693 | AL15: =(M15/L15)+(AD15/AB15)+(AF15/AE15) -> 0.41530168 | AM15: =IF(M15/L15<=0.15,AL15,MAX(AJ15,AK15)) -> 0.41530168 | AN15: =IF(AM15<=1,"OK","NG") -> OK | AO15: =(M15/L15)+(AI15*AC15/((1-M15/AG15)*AB15)) -> 0.27130984 | AP15: =(M15/(0.6*Input_disp_check!$C$6))+(AC15/AB15) -> 0.27237906 | AQ15: =(M15/L15)+(AC15/AB15) -> 0.3068038 | AR15: =IF(M15/L15<=0.15,AQ15,MAX(AO15,AP15)) -> 0.3068038 | AS15: =IF(AR15<=1,"OK","NG") -> OK | AT15: =MIN(0.4*Input_disp_check!$C$6,0.33*Input_disp_check!$C$7) -> 110 | AU15: =(INDEX(Input_disp_check!$I$42:$I$58, MATCH(B15,Input_disp_check!$B$42:$B$58,0)))/INDEX(profile_H!$T$6:$T$17, MATCH(E15, profile_H!$C$6:$C$17, 0)) -> 7.4717333 | AV15: =AU15/AT15 -> 0.067924848 | AW15: =IF(AV15<=1,"OK","NG") -> OK
B16: 3 | C16: =(INDEX(Input_disp_check!$C$42:$C$58, MATCH(B16,Input_disp_check!$B$42:$B$58,0))) -> 3000 | D16: =(INDEX(Input_disp_check!$D$42:$D$58, MATCH(B16,Input_disp_check!$B$42:$B$58,0))) -> H - | E16: =(INDEX(Input_disp_check!$E$42:$E$58, MATCH(B16,Input_disp_check!$B$42:$B$58,0))) -> 125 | F16: =SQRT(2*PI()^2*Input_disp_check!$C$8/Input_disp_check!$C$6) -> 122.7745 | G16: 2 | H16: =G16*C16/(INDEX(profile_H!$O$6:$O$17, MATCH(E16, profile_H!$C$6:$C$17, 0))) -> 192.92605 | I16: =IF(H16>200, "N.G","OK") -> OK | J16: =12*PI()^2*Input_disp_check!$C$8/(23*H16^2) -> 29.052983 | K16: =(1-H16^2/(2*F16^2))*Input_disp_check!$C$6 / ((5/3) + (3*H16/(8*F16))-(H16^3/(8*F16^3))) -> -36.434283 | L16: =IF(H16<F16,K16,J16) -> 29.052983 | M16: =(INDEX(Input_disp_check!$I$42:$I$58, MATCH(B16,Input_disp_check!$B$42:$B$58,0)))/(INDEX(profile_H!$H$6:$H$17, MATCH(E16, profile_H!$C$6:$C$17, 0))) -> 1.2941801 | N16: =IF(M16/Input_disp_check!$C$6<=0.16,"OK","Warning") -> OK | O16: =200*(INDEX(profile_H!$D$6:$D$17, MATCH(E16, profile_H!$C$6:$C$17, 0)))/SQRT(Input_disp_check!$C$6) -> 1507.5567 | P16: =138000/(E16/((INDEX(profile_H!$D$6:$D$17, MATCH(E16, profile_H!$C$6:$C$17, 0)))*(INDEX(profile_H!$F$6:$F$17, MATCH(E16, profile_H!$C$6:$C$17, 0))))*Input_disp_check!$C$6) -> 4516.3636 | Q16: =MIN(O16:P16) -> 1507.5567 | R16: =INDEX(profile_H!$I$6:$I$17, MATCH(E16, profile_H!$C$6:$C$17, 0)) -> 34.362506 | S16: =(C16)/R16 -> 87.304458 | T16: =(703.3*1000*V16/Input_disp_check!$C$6)^0.5 -> 50.571282 | U16: =(3516*1000*V16/Input_disp_check!$C$6)^0.5 -> 113.07278 | V16: 1 | W16: =MIN(0.66*Input_disp_check!$C$6, 0.55*Input_disp_check!$C$7) -> 181.5 | X16: =MIN(((2/3)-(Input_disp_check!$C$6*(C16/R16)^2 / (10550 * 1000*V16))),0.6) * Input_disp_check!$C$6 -> 128.69647 | Y16: =MIN((1172*1000*V16)/(C16/R16)^2, 0.6*Input_disp_check!$C$6) -> 153.76404 | Z16: =MIN((82740*V16)/(C16*E16/INDEX(profile_H!$U$6:$U$17, MATCH(E16, profile_H!$C$6:$C$17, 0))), 0.6*Input_disp_check!$C$6) -> 165 | AA16: =MAX(IF(S16>=T16,IF(S16<=U16,X16,Y16), Z16),Z16) -> 165 | AB16: =IF(C16>Q16,AA16,W16) -> 165 | AC16: =(INDEX(Input_disp_check!$P$42:$P$58, MATCH(B16,Input_disp_check!$B$42:$B$58,0)))/INDEX(profile_H!$K$6:$K$17,MATCH(E16, profile_H!$C$6:$C$17, 0)) -> 34.611706 | AD16: =(INDEX(Input_disp_check!$N$42:$N$58, MATCH(B16,Input_disp_check!$B$42:$B$58,0)))/INDEX(profile_H!$K$6:$K$17,MATCH(E16, profile_H!$C$6:$C$17, 0)) -> 8.6529265 | AE16: =MIN(0.75*Input_disp_check!$C$6,0.63*Input_disp_check!$C$7) -> 206.25 | AF16: =(INDEX(Input_disp_check!$Q$42:$Q$58, MATCH(B16,Input_disp_check!$B$42:$B$58,0)))/INDEX(profile_H!$N$6:$N$17, MATCH(E16, profile_H!$C$6:$C$17, 0)) -> 50.076511 | AG16: =12*PI()^2*Input_disp_check!$C$8/(23*(G16*C16/INDEX(profile_H!$L$6:$L$17, MATCH(E16, profile_H!$C$6:$C$17, 0)))^2) -> 84.058434 | AH16: =12*PI()^2*Input_disp_check!$C$8/(23*(G16*C16/INDEX(profile_H!$O$6:$O$17, MATCH(E16, profile_H!$C$6:$C$17, 0)))^2) -> 29.052983 | AI16: 0.85 | AJ16: =(M16/L16)+(AI16*AD16/((1-M16/AG16)*AB16))+(AI16*AF16/((1-M16/AH16)*AE16)) -> 0.30581588 | AK16: =(M16/(0.6*Input_disp_check!$C$6))+(AD16/AB16)+(AF16/AE16) -> 0.3030807 | AL16: =(M16/L16)+(AD16/AB16)+(AF16/AE16) -> 0.3397827 | AM16: =IF(M16/L16<=0.15,AL16,MAX(AJ16,AK16)) -> 0.3397827 | AN16: =IF(AM16<=1,"OK","NG") -> OK | AO16: =(M16/L16)+(AI16*AC16/((1-M16/AG16)*AB16)) -> 0.22563635 | AP16: =(M16/(0.6*Input_disp_check!$C$6))+(AC16/AB16) -> 0.21761143 | AQ16: =(M16/L16)+(AC16/AB16) -> 0.25431343 | AR16: =IF(M16/L16<=0.15,AQ16,MAX(AO16,AP16)) -> 0.25431343 | AS16: =IF(AR16<=1,"OK","NG") -> OK | AT16: =MIN(0.4*Input_disp_check!$C$6,0.33*Input_disp_check!$C$7) -> 110 | AU16: =(INDEX(Input_disp_check!$I$42:$I$58, MATCH(B16,Input_disp_check!$B$42:$B$58,0)))/INDEX(profile_H!$T$6:$T$17, MATCH(E16, profile_H!$C$6:$C$17, 0)) -> 4.8278892 | AV16: =AU16/AT16 -> 0.043889902 | AW16: =IF(AV16<=1,"OK","NG") -> OK
B17: 4 | C17: =(INDEX(Input_disp_check!$C$42:$C$58, MATCH(B17,Input_disp_check!$B$42:$B$58,0))) -> 2500 | D17: =(INDEX(Input_disp_check!$D$42:$D$58, MATCH(B17,Input_disp_check!$B$42:$B$58,0))) -> H - | E17: =(INDEX(Input_disp_check!$E$42:$E$58, MATCH(B17,Input_disp_check!$B$42:$B$58,0))) -> 200 | F17: =SQRT(2*PI()^2*Input_disp_check!$C$8/Input_disp_check!$C$6) -> 122.7745 | G17: 2 | H17: =G17*C17/(INDEX(profile_H!$O$6:$O$17, MATCH(E17, profile_H!$C$6:$C$17, 0))) -> 99.601594 | I17: =IF(H17>200, "N.G","OK") -> OK | J17: =12*PI()^2*Input_disp_check!$C$8/(23*H17^2) -> 109.00336 | K17: =(1-H17^2/(2*F17^2))*Input_disp_check!$C$6 / ((5/3) + (3*H17/(8*F17))-(H17^3/(8*F17^3))) -> 96.896969 | L17: =IF(H17<F17,K17,J17) -> 96.896969 | M17: =(INDEX(Input_disp_check!$I$42:$I$58, MATCH(B17,Input_disp_check!$B$42:$B$58,0)))/(INDEX(profile_H!$H$6:$H$17, MATCH(E17, profile_H!$C$6:$C$17, 0))) -> 4.6308752 | N17: =IF(M17/Input_disp_check!$C$6<=0.16,"OK","Warning") -> OK | O17: =200*(INDEX(profile_H!$D$6:$D$17, MATCH(E17, profile_H!$C$6:$C$17, 0)))/SQRT(Input_disp_check!$C$6) -> 2412.0908 | P17: =138000/(E17/((INDEX(profile_H!$D$6:$D$17, MATCH(E17, profile_H!$C$6:$C$17, 0)))*(INDEX(profile_H!$F$6:$F$17, MATCH(E17, profile_H!$C$6:$C$17, 0))))*Input_disp_check!$C$6) -> 6021.8182 | Q17: =MIN(O17:P17) -> 2412.0908 | R17: =INDEX(profile_H!$I$6:$I$17, MATCH(E17, profile_H!$C$6:$C$17, 0)) -> 55.108187 | S17: =(C17)/R17 -> 45.36531 | T17: =(703.3*1000*V17/Input_disp_check!$C$6)^0.5 -> 50.571282 | U17: =(3516*1000*V17/Input_disp_check!$C$6)^0.5 -> 113.07278 | V17: 1 | W17: =MIN(0.66*Input_disp_check!$C$6, 0.55*Input_disp_check!$C$7) -> 181.5 | X17: =MIN(((2/3)-(Input_disp_check!$C$6*(C17/R17)^2 / (10550 * 1000*V17))),0.6) * Input_disp_check!$C$6 -> 165 | Y17: =MIN((1172*1000*V17)/(C17/R17)^2, 0.6*Input_disp_check!$C$6) -> 165 | Z17: =MIN((82740*V17)/(C17*E17/INDEX(profile_H!$U$6:$U$17, MATCH(E17, profile_H!$C$6:$C$17, 0))), 0.6*Input_disp_check!$C$6) -> 165 | AA17: =MAX(IF(S17>=T17,IF(S17<=U17,X17,Y17), Z17),Z17) -> 165 | AB17: =IF(C17>Q17,AA17,W17) -> 165 | AC17: =(INDEX(Input_disp_check!$P$42:$P$58, MATCH(B17,Input_disp_check!$B$42:$B$58,0)))/INDEX(profile_H!$K$6:$K$17,MATCH(E17, profile_H!$C$6:$C$17, 0)) -> 65.446923 | AD17: =(INDEX(Input_disp_check!$N$42:$N$58, MATCH(B17,Input_disp_check!$B$42:$B$58,0)))/INDEX(profile_H!$K$6:$K$17,MATCH(E17, profile_H!$C$6:$C$17, 0)) -> 18.699121 | AE17: =MIN(0.75*Input_disp_check!$C$6,0.63*Input_disp_check!$C$7) -> 206.25 | AF17: =(INDEX(Input_disp_check!$Q$42:$Q$58, MATCH(B17,Input_disp_check!$B$42:$B$58,0)))/INDEX(profile_H!$N$6:$N$17, MATCH(E17, profile_H!$C$6:$C$17, 0)) -> 91.937344 | AG17: =12*PI()^2*Input_disp_check!$C$8/(23*(G17*C17/INDEX(profile_H!$L$6:$L$17, MATCH(E17, profile_H!$C$6:$C$17, 0)))^2) -> 321.40081 | AH17: =12*PI()^2*Input_disp_check!$C$8/(23*(G17*C17/INDEX(profile_H!$O$6:$O$17, MATCH(E17, profile_H!$C$6:$C$17, 0)))^2) -> 109.00336 | AI17: 0.85 | AJ17: =(M17/L17)+(AI17*AD17/((1-M17/AG17)*AB17))+(AI17*AF17/((1-M17/AH17)*AE17)) -> 0.5412331 | AK17: =(M17/(0.6*Input_disp_check!$C$6))+(AD17/AB17)+(AF17/AE17) -> 0.58715073 | AL17: =(M17/L17)+(AD17/AB17)+(AF17/AE17) -> 0.60687657 | AM17: =IF(M17/L17<=0.15,AL17,MAX(AJ17,AK17)) -> 0.60687657 | AN17: =IF(AM17<=1,"OK","NG") -> OK | AO17: =(M17/L17)+(AI17*AC17/((1-M17/AG17)*AB17)) -> 0.38987138 | AP17: =(M17/(0.6*Input_disp_check!$C$6))+(AC17/AB17) -> 0.42471393 | AQ17: =(M17/L17)+(AC17/AB17) -> 0.44443976 | AR17: =IF(M17/L17<=0.15,AQ17,MAX(AO17,AP17)) -> 0.44443976 | AS17: =IF(AR17<=1,"OK","NG") -> OK | AT17: =MIN(0.4*Input_disp_check!$C$6,0.33*Input_disp_check!$C$7) -> 110 | AU17: =(INDEX(Input_disp_check!$I$42:$I$58, MATCH(B17,Input_disp_check!$B$42:$B$58,0)))/INDEX(profile_H!$T$6:$T$17, MATCH(E17, profile_H!$C$6:$C$17, 0)) -> 18.387469 | AV17: =AU17/AT17 -> 0.16715881 | AW17: =IF(AV17<=1,"OK","NG") -> OK
B18: 5 | C18: =(INDEX(Input_disp_check!$C$42:$C$58, MATCH(B18,Input_disp_check!$B$42:$B$58,0))) -> 2500 | D18: =(INDEX(Input_disp_check!$D$42:$D$58, MATCH(B18,Input_disp_check!$B$42:$B$58,0))) -> H - | E18: =(INDEX(Input_disp_check!$E$42:$E$58, MATCH(B18,Input_disp_check!$B$42:$B$58,0))) -> 150 | F18: =SQRT(2*PI()^2*Input_disp_check!$C$8/Input_disp_check!$C$6) -> 122.7745 | G18: 2 | H18: =G18*C18/(INDEX(profile_H!$O$6:$O$17, MATCH(E18, profile_H!$C$6:$C$17, 0))) -> 133.33333 | I18: =IF(H18>200, "N.G","OK") -> OK | J18: =12*PI()^2*Input_disp_check!$C$8/(23*H18^2) -> 60.826801 | K18: =(1-H18^2/(2*F18^2))*Input_disp_check!$C$6 / ((5/3) + (3*H18/(8*F18))-(H18^3/(8*F18^3))) -> 58.956892 | L18: =IF(H18<F18,K18,J18) -> 60.826801 | M18: =(INDEX(Input_disp_check!$I$42:$I$58, MATCH(B18,Input_disp_check!$B$42:$B$58,0)))/(INDEX(profile_H!$H$6:$H$17, MATCH(E18, profile_H!$C$6:$C$17, 0))) -> 2.5652672 | N18: =IF(M18/Input_disp_check!$C$6<=0.16,"OK","Warning") -> OK | O18: =200*(INDEX(profile_H!$D$6:$D$17, MATCH(E18, profile_H!$C$6:$C$17, 0)))/SQRT(Input_disp_check!$C$6) -> 1809.0681 | P18: =138000/(E18/((INDEX(profile_H!$D$6:$D$17, MATCH(E18, profile_H!$C$6:$C$17, 0)))*(INDEX(profile_H!$F$6:$F$17, MATCH(E18, profile_H!$C$6:$C$17, 0))))*Input_disp_check!$C$6) -> 5018.1818 | Q18: =MIN(O18:P18) -> 1809.0681 | R18: =INDEX(profile_H!$I$6:$I$17, MATCH(E18, profile_H!$C$6:$C$17, 0)) -> 41.269848 | S18: =(C18)/R18 -> 60.576913 | T18: =(703.3*1000*V18/Input_disp_check!$C$6)^0.5 -> 50.571282 | U18: =(3516*1000*V18/Input_disp_check!$C$6)^0.5 -> 113.07278 | V18: 1 | W18: =MIN(0.66*Input_disp_check!$C$6, 0.55*Input_disp_check!$C$7) -> 181.5 | X18: =MIN(((2/3)-(Input_disp_check!$C$6*(C18/R18)^2 / (10550 * 1000*V18))),0.6) * Input_disp_check!$C$6 -> 157.02901 | Y18: =MIN((1172*1000*V18)/(C18/R18)^2, 0.6*Input_disp_check!$C$6) -> 165 | Z18: =MIN((82740*V18)/(C18*E18/INDEX(profile_H!$U$6:$U$17, MATCH(E18, profile_H!$C$6:$C$17, 0))), 0.6*Input_disp_check!$C$6) -> 165 | AA18: =MAX(IF(S18>=T18,IF(S18<=U18,X18,Y18), Z18),Z18) -> 165 | AB18: =IF(C18>Q18,AA18,W18) -> 165 | AC18: =(INDEX(Input_disp_check!$P$42:$P$58, MATCH(B18,Input_disp_check!$B$42:$B$58,0)))/INDEX(profile_H!$K$6:$K$17,MATCH(E18, profile_H!$C$6:$C$17, 0)) -> 49.369094 | AD18: =(INDEX(Input_disp_check!$N$42:$N$58, MATCH(B18,Input_disp_check!$B$42:$B$58,0)))/INDEX(profile_H!$K$6:$K$17,MATCH(E18, profile_H!$C$6:$C$17, 0)) -> 14.105455 | AE18: =MIN(0.75*Input_disp_check!$C$6,0.63*Input_disp_check!$C$7) -> 206.25 | AF18: =(INDEX(Input_disp_check!$Q$42:$Q$58, MATCH(B18,Input_disp_check!$B$42:$B$58,0)))/INDEX(profile_H!$N$6:$N$17, MATCH(E18, profile_H!$C$6:$C$17, 0)) -> 68.555143 | AG18: =12*PI()^2*Input_disp_check!$C$8/(23*(G18*C18/INDEX(profile_H!$L$6:$L$17, MATCH(E18, profile_H!$C$6:$C$17, 0)))^2) -> 176.61767 | AH18: =12*PI()^2*Input_disp_check!$C$8/(23*(G18*C18/INDEX(profile_H!$O$6:$O$17, MATCH(E18, profile_H!$C$6:$C$17, 0)))^2) -> 60.826801 | AI18: 0.85 | AJ18: =(M18/L18)+(AI18*AD18/((1-M18/AG18)*AB18))+(AI18*AF18/((1-M18/AH18)*AE18)) -> 0.41087889 | AK18: =(M18/(0.6*Input_disp_check!$C$6))+(AD18/AB18)+(AF18/AE18) -> 0.43342326 | AL18: =(M18/L18)+(AD18/AB18)+(AF18/AE18) -> 0.46004949 | AM18: =IF(M18/L18<=0.15,AL18,MAX(AJ18,AK18)) -> 0.46004949 | AN18: =IF(AM18<=1,"OK","NG") -> OK | AO18: =(M18/L18)+(AI18*AC18/((1-M18/AG18)*AB18)) -> 0.30024731 | AP18: =(M18/(0.6*Input_disp_check!$C$6))+(AC18/AB18) -> 0.31475371 | AQ18: =(M18/L18)+(AC18/AB18) -> 0.34137994 | AR18: =IF(M18/L18<=0.15,AQ18,MAX(AO18,AP18)) -> 0.34137994 | AS18: =IF(AR18<=1,"OK","NG") -> OK | AT18: =MIN(0.4*Input_disp_check!$C$6,0.33*Input_disp_check!$C$7) -> 110 | AU18: =(INDEX(Input_disp_check!$I$42:$I$58, MATCH(B18,Input_disp_check!$B$42:$B$58,0)))/INDEX(profile_H!$T$6:$T$17, MATCH(E18, profile_H!$C$6:$C$17, 0)) -> 9.80665 | AV18: =AU18/AT18 -> 0.089151364 | AW18: =IF(AV18<=1,"OK","NG") -> OK
B19: 6 | C19: =(INDEX(Input_disp_check!$C$42:$C$58, MATCH(B19,Input_disp_check!$B$42:$B$58,0))) -> 2500 | D19: =(INDEX(Input_disp_check!$D$42:$D$58, MATCH(B19,Input_disp_check!$B$42:$B$58,0))) -> H - | E19: =(INDEX(Input_disp_check!$E$42:$E$58, MATCH(B19,Input_disp_check!$B$42:$B$58,0))) -> 125 | F19: =SQRT(2*PI()^2*Input_disp_check!$C$8/Input_disp_check!$C$6) -> 122.7745 | G19: 2 | H19: =G19*C19/(INDEX(profile_H!$O$6:$O$17, MATCH(E19, profile_H!$C$6:$C$17, 0))) -> 160.7717 | I19: =IF(H19>200, "N.G","OK") -> OK | J19: =12*PI()^2*Input_disp_check!$C$8/(23*H19^2) -> 41.836295 | K19: =(1-H19^2/(2*F19^2))*Input_disp_check!$C$6 / ((5/3) + (3*H19/(8*F19))-(H19^3/(8*F19^3))) -> 20.894968 | L19: =IF(H19<F19,K19,J19) -> 41.836295 | M19: =(INDEX(Input_disp_check!$I$42:$I$58, MATCH(B19,Input_disp_check!$B$42:$B$58,0)))/(INDEX(profile_H!$H$6:$H$17, MATCH(E19, profile_H!$C$6:$C$17, 0))) -> 1.7794977 | N19: =IF(M19/Input_disp_check!$C$6<=0.16,"OK","Warning") -> OK | O19: =200*(INDEX(profile_H!$D$6:$D$17, MATCH(E19, profile_H!$C$6:$C$17, 0)))/SQRT(Input_disp_check!$C$6) -> 1507.5567 | P19: =138000/(E19/((INDEX(profile_H!$D$6:$D$17, MATCH(E19, profile_H!$C$6:$C$17, 0)))*(INDEX(profile_H!$F$6:$F$17, MATCH(E19, profile_H!$C$6:$C$17, 0))))*Input_disp_check!$C$6) -> 4516.3636 | Q19: =MIN(O19:P19) -> 1507.5567 | R19: =INDEX(profile_H!$I$6:$I$17, MATCH(E19, profile_H!$C$6:$C$17, 0)) -> 34.362506 | S19: =(C19)/R19 -> 72.753715 | T19: =(703.3*1000*V19/Input_disp_check!$C$6)^0.5 -> 50.571282 | U19: =(3516*1000*V19/Input_disp_check!$C$6)^0.5 -> 113.07278 | V19: 1 | W19: =MIN(0.66*Input_disp_check!$C$6, 0.55*Input_disp_check!$C$7) -> 181.5 | X19: =MIN(((2/3)-(Input_disp_check!$C$6*(C19/R19)^2 / (10550 * 1000*V19))),0.6) * Input_disp_check!$C$6 -> 145.39107 | Y19: =MIN((1172*1000*V19)/(C19/R19)^2, 0.6*Input_disp_check!$C$6) -> 165 | Z19: =MIN((82740*V19)/(C19*E19/INDEX(profile_H!$U$6:$U$17, MATCH(E19, profile_H!$C$6:$C$17, 0))), 0.6*Input_disp_check!$C$6) -> 165 | AA19: =MAX(IF(S19>=T19,IF(S19<=U19,X19,Y19), Z19),Z19) -> 165 | AB19: =IF(C19>Q19,AA19,W19) -> 165 | AC19: =(INDEX(Input_disp_check!$P$42:$P$58, MATCH(B19,Input_disp_check!$B$42:$B$58,0)))/INDEX(profile_H!$K$6:$K$17,MATCH(E19, profile_H!$C$6:$C$17, 0)) -> 41.642209 | AD19: =(INDEX(Input_disp_check!$N$42:$N$58, MATCH(B19,Input_disp_check!$B$42:$B$58,0)))/INDEX(profile_H!$K$6:$K$17,MATCH(E19, profile_H!$C$6:$C$17, 0)) -> 11.897774 | AE19: =MIN(0.75*Input_disp_check!$C$6,0.63*Input_disp_check!$C$7) -> 206.25 | AF19: =(INDEX(Input_disp_check!$Q$42:$Q$58, MATCH(B19,Input_disp_check!$B$42:$B$58,0)))/INDEX(profile_H!$N$6:$N$17, MATCH(E19, profile_H!$C$6:$C$17, 0)) -> 57.379335 | AG19: =12*PI()^2*Input_disp_check!$C$8/(23*(G19*C19/INDEX(profile_H!$L$6:$L$17, MATCH(E19, profile_H!$C$6:$C$17, 0)))^2) -> 121.04414 | AH19: =12*PI()^2*Input_disp_check!$C$8/(23*(G19*C19/INDEX(profile_H!$O$6:$O$17, MATCH(E19, profile_H!$C$6:$C$17, 0)))^2) -> 41.836295 | AI19: 0.85 | AJ19: =(M19/L19)+(AI19*AD19/((1-M19/AG19)*AB19))+(AI19*AF19/((1-M19/AH19)*AE19)) -> 0.3517184 | AK19: =(M19/(0.6*Input_disp_check!$C$6))+(AD19/AB19)+(AF19/AE19) -> 0.36109539 | AL19: =(M19/L19)+(AD19/AB19)+(AF19/AE19) -> 0.39284534 | AM19: =IF(M19/L19<=0.15,AL19,MAX(AJ19,AK19)) -> 0.39284534 | AN19: =IF(AM19<=1,"OK","NG") -> OK | AO19: =(M19/L19)+(AI19*AC19/((1-M19/AG19)*AB19)) -> 0.26025602 | AP19: =(M19/(0.6*Input_disp_check!$C$6))+(AC19/AB19) -> 0.26316186 | AQ19: =(M19/L19)+(AC19/AB19) -> 0.2949118 | AR19: =IF(M19/L19<=0.15,AQ19,MAX(AO19,AP19)) -> 0.2949118 | AS19: =IF(AR19<=1,"OK","NG") -> OK | AT19: =MIN(0.4*Input_disp_check!$C$6,0.33*Input_disp_check!$C$7) -> 110 | AU19: =(INDEX(Input_disp_check!$I$42:$I$58, MATCH(B19,Input_disp_check!$B$42:$B$58,0)))/INDEX(profile_H!$T$6:$T$17, MATCH(E19, profile_H!$C$6:$C$17, 0)) -> 6.6383477 | AV19: =AU19/AT19 -> 0.060348615 | AW19: =IF(AV19<=1,"OK","NG") -> OK
B20: 7 | C20: =(INDEX(Input_disp_check!$C$42:$C$58, MATCH(B20,Input_disp_check!$B$42:$B$58,0))) -> 2100 | D20: =(INDEX(Input_disp_check!$D$42:$D$58, MATCH(B20,Input_disp_check!$B$42:$B$58,0))) -> H - | E20: =(INDEX(Input_disp_check!$E$42:$E$58, MATCH(B20,Input_disp_check!$B$42:$B$58,0))) -> 200 | F20: =SQRT(2*PI()^2*Input_disp_check!$C$8/Input_disp_check!$C$6) -> 122.7745 | G20: 2 | H20: =G20*C20/(INDEX(profile_H!$O$6:$O$17, MATCH(E20, profile_H!$C$6:$C$17, 0))) -> 83.665339 | I20: =IF(H20>200, "N.G","OK") -> OK | J20: =12*PI()^2*Input_disp_check!$C$8/(23*H20^2) -> 154.48322 | K20: =(1-H20^2/(2*F20^2))*Input_disp_check!$C$6 / ((5/3) + (3*H20/(8*F20))-(H20^3/(8*F20^3))) -> 112.15411 | L20: =IF(H20<F20,K20,J20) -> 112.15411 | M20: =(INDEX(Input_disp_check!$I$42:$I$58, MATCH(B20,Input_disp_check!$B$42:$B$58,0)))/(INDEX(profile_H!$H$6:$H$17, MATCH(E20, profile_H!$C$6:$C$17, 0))) -> 5.9429565 | N20: =IF(M20/Input_disp_check!$C$6<=0.16,"OK","Warning") -> OK | O20: =200*(INDEX(profile_H!$D$6:$D$17, MATCH(E20, profile_H!$C$6:$C$17, 0)))/SQRT(Input_disp_check!$C$6) -> 2412.0908 | P20: =138000/(E20/((INDEX(profile_H!$D$6:$D$17, MATCH(E20, profile_H!$C$6:$C$17, 0)))*(INDEX(profile_H!$F$6:$F$17, MATCH(E20, profile_H!$C$6:$C$17, 0))))*Input_disp_check!$C$6) -> 6021.8182 | Q20: =MIN(O20:P20) -> 2412.0908 | R20: =INDEX(profile_H!$I$6:$I$17, MATCH(E20, profile_H!$C$6:$C$17, 0)) -> 55.108187 | S20: =(C20)/R20 -> 38.106861 | T20: =(703.3*1000*V20/Input_disp_check!$C$6)^0.5 -> 50.571282 | U20: =(3516*1000*V20/Input_disp_check!$C$6)^0.5 -> 113.07278 | V20: 1 | W20: =MIN(0.66*Input_disp_check!$C$6, 0.55*Input_disp_check!$C$7) -> 181.5 | X20: =MIN(((2/3)-(Input_disp_check!$C$6*(C20/R20)^2 / (10550 * 1000*V20))),0.6) * Input_disp_check!$C$6 -> 165 | Y20: =MIN((1172*1000*V20)/(C20/R20)^2, 0.6*Input_disp_check!$C$6) -> 165 | Z20: =MIN((82740*V20)/(C20*E20/INDEX(profile_H!$U$6:$U$17, MATCH(E20, profile_H!$C$6:$C$17, 0))), 0.6*Input_disp_check!$C$6) -> 165 | AA20: =MAX(IF(S20>=T20,IF(S20<=U20,X20,Y20), Z20),Z20) -> 165 | AB20: =IF(C20>Q20,AA20,W20) -> 181.5 | AC20: =(INDEX(Input_disp_check!$P$42:$P$58, MATCH(B20,Input_disp_check!$B$42:$B$58,0)))/INDEX(profile_H!$K$6:$K$17,MATCH(E20, profile_H!$C$6:$C$17, 0)) -> 74.391335 | AD20: =(INDEX(Input_disp_check!$N$42:$N$58, MATCH(B20,Input_disp_check!$B$42:$B$58,0)))/INDEX(profile_H!$K$6:$K$17,MATCH(E20, profile_H!$C$6:$C$17, 0)) -> 23.997205 | AE20: =MIN(0.75*Input_disp_check!$C$6,0.63*Input_disp_check!$C$7) -> 206.25 | AF20: =(INDEX(Input_disp_check!$Q$42:$Q$58, MATCH(B20,Input_disp_check!$B$42:$B$58,0)))/INDEX(profile_H!$N$6:$N$17, MATCH(E20, profile_H!$C$6:$C$17, 0)) -> 99.108457 | AG20: =12*PI()^2*Input_disp_check!$C$8/(23*(G20*C20/INDEX(profile_H!$L$6:$L$17, MATCH(E20, profile_H!$C$6:$C$17, 0)))^2) -> 455.50002 | AH20: =12*PI()^2*Input_disp_check!$C$8/(23*(G20*C20/INDEX(profile_H!$O$6:$O$17, MATCH(E20, profile_H!$C$6:$C$17, 0)))^2) -> 154.48322 | AI20: 0.85 | AJ20: =(M20/L20)+(AI20*AD20/((1-M20/AG20)*AB20))+(AI20*AF20/((1-M20/AH20)*AE20)) -> 0.59164702 | AK20: =(M20/(0.6*Input_disp_check!$C$6))+(AD20/AB20)+(AF20/AE20) -> 0.64875977 | AL20: =(M20/L20)+(AD20/AB20)+(AF20/AE20) -> 0.66573105 | AM20: =IF(M20/L20<=0.15,AL20,MAX(AJ20,AK20)) -> 0.66573105 | AN20: =IF(AM20<=1,"OK","NG") -> OK | AO20: =(M20/L20)+(AI20*AC20/((1-M20/AG20)*AB20)) -> 0.40598393 | AP20: =(M20/(0.6*Input_disp_check!$C$6))+(AC20/AB20) -> 0.44588753 | AQ20: =(M20/L20)+(AC20/AB20) -> 0.46285881 | AR20: =IF(M20/L20<=0.15,AQ20,MAX(AO20,AP20)) -> 0.46285881 | AS20: =IF(AR20<=1,"OK","NG") -> OK | AT20: =MIN(0.4*Input_disp_check!$C$6,0.33*Input_disp_check!$C$7) -> 110 | AU20: =(INDEX(Input_disp_check!$I$42:$I$58, MATCH(B20,Input_disp_check!$B$42:$B$58,0)))/INDEX(profile_H!$T$6:$T$17, MATCH(E20, profile_H!$C$6:$C$17, 0)) -> 23.597252 | AV20: =AU20/AT20 -> 0.21452047 | AW20: =IF(AV20<=1,"OK","NG") -> OK
B21: 8 | C21: =(INDEX(Input_disp_check!$C$42:$C$58, MATCH(B21,Input_disp_check!$B$42:$B$58,0))) -> 2100 | D21: =(INDEX(Input_disp_check!$D$42:$D$58, MATCH(B21,Input_disp_check!$B$42:$B$58,0))) -> H - | E21: =(INDEX(Input_disp_check!$E$42:$E$58, MATCH(B21,Input_disp_check!$B$42:$B$58,0))) -> 150 | F21: =SQRT(2*PI()^2*Input_disp_check!$C$8/Input_disp_check!$C$6) -> 122.7745 | G21: 2 | H21: =G21*C21/(INDEX(profile_H!$O$6:$O$17, MATCH(E21, profile_H!$C$6:$C$17, 0))) -> 112 | I21: =IF(H21>200, "N.G","OK") -> OK | J21: =12*PI()^2*Input_disp_check!$C$8/(23*H21^2) -> 86.205784 | K21: =(1-H21^2/(2*F21^2))*Input_disp_check!$C$6 / ((5/3) + (3*H21/(8*F21))-(H21^3/(8*F21^3))) -> 83.900783 | L21: =IF(H21<F21,K21,J21) -> 83.900783 | M21: =(INDEX(Input_disp_check!$I$42:$I$58, MATCH(B21,Input_disp_check!$B$42:$B$58,0)))/(INDEX(profile_H!$H$6:$H$17, MATCH(E21, profile_H!$C$6:$C$17, 0))) -> 3.2982007 | N21: =IF(M21/Input_disp_check!$C$6<=0.16,"OK","Warning") -> OK | O21: =200*(INDEX(profile_H!$D$6:$D$17, MATCH(E21, profile_H!$C$6:$C$17, 0)))/SQRT(Input_disp_check!$C$6) -> 1809.0681 | P21: =138000/(E21/((INDEX(profile_H!$D$6:$D$17, MATCH(E21, profile_H!$C$6:$C$17, 0)))*(INDEX(profile_H!$F$6:$F$17, MATCH(E21, profile_H!$C$6:$C$17, 0))))*Input_disp_check!$C$6) -> 5018.1818 | Q21: =MIN(O21:P21) -> 1809.0681 | R21: =INDEX(profile_H!$I$6:$I$17, MATCH(E21, profile_H!$C$6:$C$17, 0)) -> 41.269848 | S21: =(C21)/R21 -> 50.884607 | T21: =(703.3*1000*V21/Input_disp_check!$C$6)^0.5 -> 50.571282 | U21: =(3516*1000*V21/Input_disp_check!$C$6)^0.5 -> 113.07278 | V21: 1 | W21: =MIN(0.66*Input_disp_check!$C$6, 0.55*Input_disp_check!$C$7) -> 181.5 | X21: =MIN(((2/3)-(Input_disp_check!$C$6*(C21/R21)^2 / (10550 * 1000*V21))),0.6) * Input_disp_check!$C$6 -> 164.773 | Y21: =MIN((1172*1000*V21)/(C21/R21)^2, 0.6*Input_disp_check!$C$6) -> 165 | Z21: =MIN((82740*V21)/(C21*E21/INDEX(profile_H!$U$6:$U$17, MATCH(E21, profile_H!$C$6:$C$17, 0))), 0.6*Input_disp_check!$C$6) -> 165 | AA21: =MAX(IF(S21>=T21,IF(S21<=U21,X21,Y21), Z21),Z21) -> 165 | AB21: =IF(C21>Q21,AA21,W21) -> 165 | AC21: =(INDEX(Input_disp_check!$P$42:$P$58, MATCH(B21,Input_disp_check!$B$42:$B$58,0)))/INDEX(profile_H!$K$6:$K$17,MATCH(E21, profile_H!$C$6:$C$17, 0)) -> 56.220315 | AD21: =(INDEX(Input_disp_check!$N$42:$N$58, MATCH(B21,Input_disp_check!$B$42:$B$58,0)))/INDEX(profile_H!$K$6:$K$17,MATCH(E21, profile_H!$C$6:$C$17, 0)) -> 18.135586 | AE21: =MIN(0.75*Input_disp_check!$C$6,0.63*Input_disp_check!$C$7) -> 206.25 | AF21: =(INDEX(Input_disp_check!$Q$42:$Q$58, MATCH(B21,Input_disp_check!$B$42:$B$58,0)))/INDEX(profile_H!$N$6:$N$17, MATCH(E21, profile_H!$C$6:$C$17, 0)) -> 74.039555 | AG21: =12*PI()^2*Input_disp_check!$C$8/(23*(G21*C21/INDEX(profile_H!$L$6:$L$17, MATCH(E21, profile_H!$C$6:$C$17, 0)))^2) -> 250.30849 | AH21: =12*PI()^2*Input_disp_check!$C$8/(23*(G21*C21/INDEX(profile_H!$O$6:$O$17, MATCH(E21, profile_H!$C$6:$C$17, 0)))^2) -> 86.205784 | AI21: 0.85 | AJ21: =(M21/L21)+(AI21*AD21/((1-M21/AG21)*AB21))+(AI21*AF21/((1-M21/AH21)*AE21)) -> 0.45125533 | AK21: =(M21/(0.6*Input_disp_check!$C$6))+(AD21/AB21)+(AF21/AE21) -> 0.48888139 | AL21: =(M21/L21)+(AD21/AB21)+(AF21/AE21) -> 0.50820302 | AM21: =IF(M21/L21<=0.15,AL21,MAX(AJ21,AK21)) -> 0.50820302 | AN21: =IF(AM21<=1,"OK","NG") -> OK | AO21: =(M21/L21)+(AI21*AC21/((1-M21/AG21)*AB21)) -> 0.33279768 | AP21: =(M21/(0.6*Input_disp_check!$C$6))+(AC21/AB21) -> 0.36071828 | AQ21: =(M21/L21)+(AC21/AB21) -> 0.38003991 | AR21: =IF(M21/L21<=0.15,AQ21,MAX(AO21,AP21)) -> 0.38003991 | AS21: =IF(AR21<=1,"OK","NG") -> OK | AT21: =MIN(0.4*Input_disp_check!$C$6,0.33*Input_disp_check!$C$7) -> 110 | AU21: =(INDEX(Input_disp_check!$I$42:$I$58, MATCH(B21,Input_disp_check!$B$42:$B$58,0)))/INDEX(profile_H!$T$6:$T$17, MATCH(E21, profile_H!$C$6:$C$17, 0)) -> 12.60855 | AV21: =AU21/AT21 -> 0.11462318 | AW21: =IF(AV21<=1,"OK","NG") -> OK
